Workbook

Sheet Dashboard
A1: Análise de Auxílios PIPE - FAPESP
A2: Visão dos projetos iniciados entre 2021 e 2025
C4: Projetos 2021-2025 | H4: Projetos em 2025 | M4: Crescimento entre 2021-2025
C5: =SUM(D13:D17) -> 1256 | H5: =D17 -> 155 | M5: =IF(SUM('4.Crescimento por Área '!B4:B56)=0,"",(SUM('4.Crescimento por Área '!F4:F56)-SUM('4.Crescimento por Área '!B4:B56))/SUM('4.Crescimento por Área '!B4:B56)) -> -0.42122186
C12: Anos | D12: Projetos
C13: 2021 | D13: =SUM('4.Crescimento por Área '!B4:B56) -> 311
C14: 2022 | D14: =SUM('4.Crescimento por Área '!C5:C57) -> 286
C15: 2023 | D15: =SUM('4.Crescimento por Área '!D6:D58) -> 311
C16: 2024 | D16: =SUM('4.Crescimento por Área '!E7:E59) -> 193
C17: 2025 | D17: =SUM('4.Crescimento por Área '!F8:F60) -> 155
C25: Área | D25: Projetos em 2025
C26: =IFERROR(__xludf.DUMMYFUNCTION("QUERY('4.Crescimento por Área '!A4:F54,""select A, F where A is not null order by F desc limit 10"",0)"),"Agronomia") -> Agronomia | D26: =IFERROR(__xludf.DUMMYFUNCTION("""COMPUTED_VALUE"""),20.0) -> 20
C27: =IFERROR(__xludf.DUMMYFUNCTION("""COMPUTED_VALUE"""),"Microbiologia") -> Microbiologia | D27: =IFERROR(__xludf.DUMMYFUNCTION("""COMPUTED_VALUE"""),15.0) -> 15
C28: =IFERROR(__xludf.DUMMYFUNCTION("""COMPUTED_VALUE"""),"Química") -> Química | D28: =IFERROR(__xludf.DUMMYFUNCTION("""COMPUTED_VALUE"""),12.0) -> 12
C29: =IFERROR(__xludf.DUMMYFUNCTION("""COMPUTED_VALUE"""),"Ciência da Computação") -> Ciência da Computação | D29: =IFERROR(__xludf.DUMMYFUNCTION("""COMPUTED_VALUE"""),11.0) -> 11
C30: =IFERROR(__xludf.DUMMYFUNCTION("""COMPUTED_VALUE"""),"Bioquímica") -> Bioquímica | D30: =IFERROR(__xludf.DUMMYFUNCTION("""COMPUTED_VALUE"""),8.0) -> 8
C31: =IFERROR(__xludf.DUMMYFUNCTION("""COMPUTED_VALUE"""),"Botânica") -> Botânica | D31: =IFERROR(__xludf.DUMMYFUNCTION("""COMPUTED_VALUE"""),8.0) -> 8
C32: =IFERROR(__xludf.DUMMYFUNCTION("""COMPUTED_VALUE"""),"Engenharia Biomédica") -> Engenharia Biomédica | D32: =IFERROR(__xludf.DUMMYFUNCTION("""COMPUTED_VALUE"""),8.0) -> 8
C33: =IFERROR(__xludf.DUMMYFUNCTION("""COMPUTED_VALUE"""),"Engenharia Mecânica") -> Engenharia Mecânica | D33: =IFERROR(__xludf.DUMMYFUNCTION("""COMPUTED_VALUE"""),8.0) -> 8
C34: =IFERROR(__xludf.DUMMYFUNCTION("""COMPUTED_VALUE"""),"Engenharia Química") -> Engenharia Química | D34: =IFERROR(__xludf.DUMMYFUNCTION("""COMPUTED_VALUE"""),8.0) -> 8
C35: =IFERROR(__xludf.DUMMYFUNCTION("""COMPUTED_VALUE"""),"Farmácia") -> Farmácia | D35: =IFERROR(__xludf.DUMMYFUNCTION("""COMPUTED_VALUE"""),8.0) -> 8

Sheet 1. Áreas e Subáreas
A2: Quantidade de Empresas por Área do Conhecimento
B3: Quantidade de Empresa(s)
A4: Ciência da Computação | B4: 532
A5: Engenharia Elétrica | B5: 511
A6: Engenharia de Materiais e Metalúrgica | B6: 439
A7: Química | B7: 297
A8: Agronomia | B8: 289
A9: Engenharia Biomédica | B9: 262
A10: Engenharia Mecânica | B10: 257
A11: Microbiologia | B11: 191
A12: Engenharia Química | B12: 191
A13: Farmácia | B13: 173
A14: Medicina | B14: 164
A15: Ciência e Tecnologia de Alimentos | B15: 142
... A65: Ciência Política | B65: 2
A69: Quantidade de Empresas por Subárea do Conhecimento
A70: Área do Conhecimento | B70: Subárea do Conhecimento | C70: Quantidade de Empresa(s)
A71: Administração | B71: Administração de Empresas | C71: 23
A72: Administração | B72: Administração de Setores Específicos | C72: 6
A73: Administração | B73: Administração Pública | C73: 3
A74: Agronomia | B74: Agrometeorologia | C74: 12
A75: Agronomia | B75: Ciência do Solo | C75: 33
A76: Agronomia | B76: Fitossanidade | C76: 124
A77: Agronomia | B77: Fitotecnia | C77: 64
A78: Agronomia | B78: Floricultura, Parques e Jardins | C78: 4
A79: Arquitetura e Urbanismo | B79: Fundamentos de Arquitetura e Urbanismo | C79: 1
A80: Arquitetura e Urbanismo | B80: Projeto de Arquitetura e Urbanismo | C80: 4
A81: Arquitetura e Urbanismo | B81: Tecnologia de Arquitetura e Urbanismo | C81: 18
A82: Artes | B82: Artes do Vídeo | C82: 4
... A163: Engenharia Mecânica | B163: Projetos de Máquinas | C163: 110
A164: Engenharia Naval e Oceânica | C164: 13
A165: Engenharia Nuclear | B165: Aplicações de Radioisótopos | C165: 22
A166: Engenharia Nuclear | B166: Tecnologia dos Reatores | C166: 1
A167: Engenharia Química | B167: Operações Industriais e Equipamentos para Engenharia Química | C167: 14
A168: Engenharia Química | B168: Processos Industriais de Engenharia Química | C168: 54
A169: Engenharia Química | B169: Tecnologia Química | C169: 85
A170: Engenharia Sanitária | B170: Recursos Hídricos | C170: 11
A171: Engenharia Sanitária | B171: Saneamento Ambiental | C171: 35
A172: Engenharia Sanitária | B172: Saneamento Básico | C172: 7
A173: Engenharia Sanitária | B173: Tratamentos de Águas de Abastecimento e Residuárias | C173: 18
...

Sheet 2. Cidades
A2: Quantidade de Empresas por Cidade
A3: Cidade | B3: Quantidade de Empresa(s)
A4: São Paulo | B4: 931
A5: Campinas | B5: 477
A6: São Carlos | B6: 432
A7: São José dos Campos | B7: 260
A8: Ribeirão Preto | B8: 194
A9: Piracicaba | B9: 138
A10: Sorocaba | B10: 58
A11: Botucatu | B11: 55
A12: Araraquara | B12: 52
A13: São José do Rio Preto | B13: 43
A14: São Caetano do Sul | B14: 31
A15: Jaboticabal | B15: 27
... A180: Leme | B180: 1

Sheet 3. Ribeirão Preto
A1: Empresas no Projeto PIPE em Ribeirão Preto
A2: Empresa | B2: Modalidade de apoio | C2: Grande Área do Conhecimento | D2: Área do Conhecimento | E2: Data de Início | F2: Data de Término
A3: Actinobac Agrosciences Pesquisa e Desenvolvimento Ltda | B3: Auxílio à Pesquisa - Pesquisa Inovativa em Pequenas Empresas - PIPE | C3: Ciências Exatas e da Terra | D3: Química | E3: 44470 | F3: 45382
A4: Actinobac Agrosciences Pesquisa e Desenvolvimento Ltda | B4: Auxílio à Pesquisa - Pesquisa Inovativa em Pequenas Empresas - PIPE | C4: Ciências Exatas e da Terra | D4: Química | E4: 43770 | F4: 44043
A5: Adiel Comercial Ltda | B5: Auxílio à Pesquisa - Pesquisa Inovativa em Pequenas Empresas - PIPE | C5: Engenharias | D5: Engenharia Elétrica | E5: 37987 | F5: 38168
A6: Adriana Ferreira Lopes Vilela | B6: Auxílio à Pesquisa - Pesquisa Inovativa em Pequenas Empresas - PIPE | C6: Ciências Exatas e da Terra | D6: Química | E6: 43891 | F6: 44165
A7: Agrobee Soluções em Polinização e Sustentabilidade Ltda | B7: Auxílio à Pesquisa - Pesquisa Inovativa em Pequenas Empresas - PIPE | C7: Ciências Agrárias | D7: Agronomia | E7: 45323 | F7: 46234
A8: Agrobee Soluções em Polinização e Sustentabilidade Ltda | B8: Auxílio à Pesquisa - Pesquisa Inovativa em Pequenas Empresas - PIPE | C8: Ciências da Saúde | D8: Farmácia | E8: 42491 | F8: 42855
A9: Agrobee Soluções em Polinização e Sustentabilidade Ltda | B9: Auxílio à Pesquisa - Pesquisa Inovativa em Pequenas Empresas - PIPE | C9: Ciências Agrárias | D9: Zootecnia | E9: 44743 | F9: 45291
A10: Agrobee Soluções em Polinização e Sustentabilidade Ltda | B10: Auxílio à Pesquisa - Pesquisa Inovativa em Pequenas Empresas - PIPE | C10: Ciências da Saúde | D10: Farmácia | E10: 42767 | F10: 43159
A11: Agrobee Soluções em Polinização e Sustentabilidade Ltda | B11: Auxílio à Pesquisa - Pesquisa Inovativa em Pequenas Empresas - PIPE | C11: Ciências Agrárias | D11: Engenharia Agrícola | E11: 44197 | F11: 44469
A12: Agrobee Soluções em Polinização e Sustentabilidade Ltda | B12: Auxílio à Pesquisa - Pesquisa Inovativa em Pequenas Empresas - PIPE | C12: Ciências Agrárias | D12: Agronomia | E12: 44835 | F12: 45565
A13: Agrobee Soluções em Polinização e Sustentabilidade Ltda | B13: Auxílio à Pesquisa - Pesquisa Inovativa em Pequenas Empresas - PIPE | C13: Ciências Agrárias | D13: Zootecnia | E13: 43160 | F13: 44255
A14: Al Sukkar Biotecnologia Industrial Ltda. - ME | B14: Auxílio à Pesquisa - Pesquisa Inovativa em Pequenas Empresas - PIPE | C14: Ciências Exatas e da Terra | D14: Química | E14: 40664 | F14: 41394
... A44: Dentillo e Gavio Identificação e Quantificação Molecular Ltda. - ME | B44: Auxílio à Pesquisa - Pesquisa Inovativa em Pequenas Empresas - PIPE | C44: Ciências da Saúde | D44: Saúde Coletiva | E44: 43525 | F44: 44804
A45: Diasci Diagnóstico Científico e Soluções Tecnológicas Avançadas Ltda | B45: Auxílio à Pesquisa - Pesquisa Inovativa em Pequenas Empresas - PIPE | C45: Interdisciplinar | E45: 44896 | F45: 45260
A46: Diasci Diagnóstico Científico e Soluções Tecnológicas Avançadas Ltda | B46: Auxílio à Pesquisa - Pesquisa Inovativa em Pequenas Empresas - PIPE | C46: Interdisciplinar | E46: 45748 | F46: 46477
A47: Eco Biotech Tecnologia em Manutenção Ltda. - ME | B47: Auxílio à Pesquisa - Pesquisa Inovativa em Pequenas Empresas - PIPE | C47: Ciências Biológicas | D47: Microbiologia | E47: 45444 | F47: 46173
A48: Eco Biotech Tecnologia em Manutenção Ltda. - ME | B48: Auxílio à Pesquisa - Pesquisa Inovativa em Pequenas Empresas - PIPE | C48: Ciências Biológicas | D48: Microbiologia | E48: 43374 | F48: 43677
A49: Eco Biotech Tecnologia em Manutenção Ltda. - ME | B49: Auxílio à Pesquisa - Pesquisa Inovativa em Pequenas Empresas - PIPE | C49: Ciências Biológicas | D49: Microbiologia | E49: 44044 | F49: 44865
A50: EDITBIO BIOTECNOLOGIA LTDA | B50: Auxílio à Pesquisa - Pesquisa Inovativa em Pequenas Empresas - PIPE | C50: Ciências Biológicas | D50: Imunologia | E50: 45627 | F50: 45900
A51: Eleve Science Pesquisa e Desenvolvimento Ltda | B51: Auxílio à Pesquisa - Pesquisa Inovativa em Pequenas Empresas - PIPE | C51: Ciências da Saúde | D51: Farmácia | E51: 43252 | F51: 44074
A52: Eleve Science Pesquisa e Desenvolvimento Ltda | B52: Auxílio à Pesquisa - Pesquisa Inovativa em Pequenas Empresas - PIPE | C52: Ciências da Saúde | D52: Farmácia | E52: 43525 | F52: 44316
A53: Eleve Science Pesquisa e Desenvolvimento Ltda | B53: Auxílio à Pesquisa - Pesquisa Inovativa em Pequenas Empresas - PIPE | C53: Ciências Biológicas | D53: Farmacologia | E53: 43770 | F53: 44592
A54: Essentii Pesquisa, Desenvolvimento e Inovação Ltda. - ME | B54: Auxílio à Pesquisa - Pesquisa Inovativa em Pequenas Empresas - PIPE | C54: Ciências da Saúde | D54: Farmácia | E54: 41000 | F54: 41912
A55: Essentii Pesquisa, Desenvolvimento e Inovação Ltda. - ME | B55: Auxílio à Pesquisa - Pesquisa Inovativa em Pequenas Empresas - PIPE | C55: Ciências da Saúde | D55: Farmácia | E55: 40422 | F55: 40694
A56: Essentii Pesquisa, Desenvolvimento e Inovação Ltda. - ME | B56: Auxílio à Pesquisa - Pesquisa Inovativa em Pequenas Empresas - PIPE | C56: Ciências da Saúde | D56: Farmácia | E56: 41760 | F56: 42613
A57: Essentii Pesquisa, Desenvolvimento e Inovação Ltda. - ME | B57: Auxílio à Pesquisa - Pesquisa Inovativa em Pequenas Empresas - PIPE | C57: Ciências da Saúde | D57: Farmácia | E57: 41760 | F57: 42613
A58: Exclusif Ltda. - EPP | B58: Auxílio à Pesquisa - Pesquisa Inovativa em Pequenas Empresas - PIPE | C58: Engenharias | D58: Engenharia Elétrica | E58: 42979 | F58: 43159
... A144: Onkos Diagnósticos Moleculares Ltda. - ME | B144: Auxílio à Pesquisa - Pesquisa Inovativa em Pequenas Empresas - PIPE | C144: Ciências da Saúde | D144: Medicina | E144: 44105 | F144: 44500
A145: Paula C dos Santos Suporte Técnico e Desenvolvimento de Sistemas Ltda | B145: Auxílio à Pesquisa - Pesquisa Inovativa em Pequenas Empresas - PIPE | C145: Interdisciplinar | E145: 45323 | F145: 45596
A146: PBF Nutrientes Ltda | B146: Auxílio à Pesquisa - Pesquisa Inovativa em Pequenas Empresas - PIPE | C146: Ciências Exatas e da Terra | D146: Química | E146: 44958 | F146: 45322
A147: PHC Serviços Administrativos e Projetos Ltda. - ME | B147: Auxílio à Pesquisa - Pesquisa Inovativa em Pequenas Empresas - PIPE | C147: Ciências Sociais Aplicadas | D147: Administração | E147: 42217 | F147: 42490
A148: Pro Bio Pesquisa e Desenvolvimento Ltda. - ME | B148: Auxílio à Pesquisa - Pesquisa Inovativa em Pequenas Empresas - PIPE | C148: Ciências da Saúde | D148: Farmácia | E148: 40210 | F148: 40482
A149: Progenix Pesquisa e Artigos para Laboratório Ltda | B149: Auxílio à Pesquisa - Pesquisa Inovativa em Pequenas Empresas - PIPE | C149: Ciências Biológicas | D149: Genética | E149: 44348 | F149: 44620
A150: Rad Tech Sistemas Médicos Ltda | B150: Auxílio à Pesquisa - Pesquisa Inovativa em Pequenas Empresas - PIPE | C150: Ciências Biológicas | D150: Biofísica | E150: 41091 | F150: 41455
A151: Radiologia IS Desenvolvimento de Programas Ltda | B151: Auxílio à Pesquisa - Pesquisa Inovativa em Pequenas Empresas - PIPE | C151: Ciências da Saúde | D151: Medicina | E151: 43770 | F151: 44043
A152: Rafael Mira de Oliveira Libardi Eireli - ME | B152: Auxílio à Pesquisa - Pesquisa Inovativa em Pequenas Empresas - PIPE | C152: Ciências Exatas e da Terra | D152: Ciência da Computação | E152: 42826 | F152: 43100
A153: Reload Health Devices Ltda | B153: Auxílio à Pesquisa - Pesquisa Inovativa em Pequenas Empresas - PIPE | C153: Ciências da Saúde | D153: Saúde Coletiva | E153: 45017 | F153: 45747
A154: Reload Health Devices Ltda | B154: Auxílio à Pesquisa - Pesquisa Inovativa em Pequenas Empresas - PIPE | C154: Ciências da Saúde | D154: Saúde Coletiva | E154: 44348 | F154: 44620
...

Sheet 4.Crescimento por Área 
A1: Crescimento dos projetos PIPE por Área do Conhecimento (2021–2025)
A2: Quantidade de Projetos | B2: Anos | G2: Evolução entre 2021 e 2025
A3: Área do Conhecimento | B3: 2021 | C3: 2022 | D3: 2023 | E3: 2024 | F3: 2025 | G3: Porcentagem(%)
A4: Administração | B4: 1 | C4: 3 | D4: 5 | E4: 0 | F4: 3 | G4: =IF(B4=0,"",(F4-B4)/B4) -> 2
A5: Agronomia | B5: 8 | C5: 21 | D5: 21 | E5: 31 | F5: 20 | G5: =IF(B5=0,"",(F5-B5)/B5) -> 1.5
A6: Arquitetura e Urbanismo | B6: 4 | C6: 3 | D6: 0 | E6: 2 | F6: 0 | G6: =IF(B6=0,"",(F6-B6)/B6) -> -1
A7: Biofísica | B7: 4 | C7: 2 | D7: 2 | E7: 0 | F7: 2 | G7: =IF(B7=0,"",(F7-B7)/B7) -> -0.5
A8: Biologia Geral | B8: 3 | C8: 10 | D8: 0 | E8: 5 | F8: 1 | G8: =IF(B8=0,"",(F8-B8)/B8) -> -0.66666667
A9: Bioquímica | B9: 13 | C9: 4 | D9: 7 | E9: 2 | F9: 8 | G9: =IF(B9=0,"",(F9-B9)/B9) -> -0.38461538
A10: Botânica | B10: 2 | C10: 0 | D10: 4 | E10: 2 | F10: 8 | G10: =IF(B10=0,"",(F10-B10)/B10) -> 3
A11: Ciência da Computação | B11: 29 | C11: 14 | D11: 48 | E11: 24 | F11: 11 | G11: =IF(B11=0,"",(F11-B11)/B11) -> -0.62068966
A12: Ciência e Tecnologia de Alimentos | B12: 9 | C12: 11 | D12: 11 | E12: 10 | F12: 3 | G12: =IF(B12=0,"",(F12-B12)/B12) -> -0.66666667
A13: Comunicação | B13: 0 | C13: 1 | D13: 1 | E13: 0 | F13: 0 | G13: =IF(B13=0,"",(F13-B13)/B13)
A14: Desenho Industrial | B14: 2 | C14: 0 | D14: 0 | E14: 0 | F14: 0 | G14: =IF(B14=0,"",(F14-B14)/B14) -> -1
A15: Ecologia | B15: 5 | C15: 2 | D15: 6 | E15: 2 | F15: 0 | G15: =IF(B15=0,"",(F15-B15)/B15) -> -1
... A56: Zootecnia | B56: 7 | C56: 17 | D56: 4 | E56: 2 | F56: 1 | G56: =IF(B56=0,"",(F56-B56)/B56) -> -0.85714286
